<?xml version="1.0"?>
<robot name="hercules">
  <link name="base_link">
    <visual>
      <geometry>
        <box size="0.29 .14 .09"/>
      </geometry>
      <origin rpy="0 0 0" xyz="0 0 0.065"/>
      <material name="blue">
        <color rgba="0 0 .8 1"/>
      </material>
    </visual>
  </link>

  <link name="right_front_wheel">
    <visual>
      <geometry>
        <cylinder length=".04" radius=".04"/>
      </geometry>
      <material name="black">
        <color rgba="0 0 0 1"/>
      </material>
    </visual>
  </link>

  <joint name="right_front_wheel_joint" type="continuous">
    <axis xyz="0 0 1"/>
    <parent link="base_link"/>
    <child link="right_front_wheel"/>
    <origin rpy="1.57075 0 0" xyz=".08 -0.088 .04"/>
    <limit effort="100" velocity="100"/>
    <joint_properties damping="0.0" friction="0.0"/>
  </joint>

  <link name="right_back_wheel">
    <visual>
      <geometry>
        <cylinder length=".04" radius=".04"/>
      </geometry>
      <material name="black">
        <color rgba="0 0 0 1"/>
      </material>
    </visual>
  </link>

  <joint name="right_back_wheel_joint" type="continuous">
    <axis xyz="0 0 1"/>
    <parent link="base_link"/>
    <child link="right_back_wheel"/>
    <origin rpy="1.57075 0 0" xyz="-0.08 -0.088 .04"/>
    <limit effort="100" velocity="100"/>
    <joint_properties damping="0.0" friction="0.0"/>
  </joint>

  <link name="left_front_wheel">
    <visual>
      <geometry>
        <cylinder length=".04" radius=".04"/>
      </geometry>
      <material name="black">
        <color rgba="0 0 0 1"/>
      </material>
    </visual>
  </link>

  <joint name="left_front_wheel_joint" type="continuous">
    <axis xyz="0 0 1"/>
    <parent link="base_link"/>
    <child link="left_front_wheel"/>
    <origin rpy="1.57075 0 0" xyz="0.08 .088 .04"/>
    <limit effort="100" velocity="100"/>
    <joint_properties damping="0.0" friction="0.0"/>
  </joint>

  <link name="left_back_wheel">
    <visual>
      <geometry>
        <cylinder length=".04" radius=".04"/>
      </geometry>
      <material name="black">
        <color rgba="0 0 0 1"/>
      </material>
    </visual>
  </link>

  <joint name="left_back_wheel_joint" type="continuous">
    <axis xyz="0 0 1"/>
    <parent link="base_link"/>
    <child link="left_back_wheel"/>
    <origin rpy="1.57075 0 0" xyz="-0.08 .088 .04"/>
    <limit effort="100" velocity="100"/>
    <joint_properties damping="0.0" friction="0.0"/>
  </joint>

  <link name="laser">
    <visual>
      <geometry>
        <cylinder length=".04" radius=".038" />
      </geometry>
      <material name="white">
        <color rgba="1 1 1 1"/>
      </material>
    </visual>
  </link>

  <joint name="laser_base" type="fixed">
    <parent link="base_link"/>
    <child link="laser"/>
    <origin rpy="3.1415927 3.1415927 0" xyz="0.06 0 .135"/>
  </joint>
</robot>


